<?xml version="1.0"?>
<robot xmlns:xacro="http://ros.org/wiki/xacro">
  <xacro:macro name="control_surface" params="ns surface_name limit *lorigin *vorigin *jorigin *axis">
    <link name="${ns}/${surface_name}">
      <inertial>
        <mass value="0.0001" />
        <inertia ixx="0.0038166" ixy="0" ixz="0" iyy="0.0036" iyz="0" izz="0.003816"/>
      </inertial>

      <visual>

        <geometry>
          <!--mesh root comes from cessna.xacro-->
          <mesh filename="${mesh_root}/${surface_name}.dae" scale="0.1 0.1 0.1"/>
        </geometry>
        <xacro:insert_block name="vorigin" />
      </visual>
    </link>

    <joint name="${ns}/${surface_name}_joint" type="revolute">
      <parent link="${ns}/base_link" />
      <child link="${ns}/${surface_name}" />
      <xacro:insert_block name="jorigin" />
      <xacro:insert_block name="axis" />
      <limit lower="${-limit}" upper="${limit}" effort="-1" velocity="-1"/>
    </joint>


    <gazebo>
      <plugin name="${surface_name}_plugin" filename="libLiftDragPlugin.so">
        <!--Look in plane.xacro for definitions-->
        <xacro:if value="${surface_name == 'left_aileron'}">
          <xacro:insert_block name="left_aileron_coeffs"/>
        </xacro:if>
        <xacro:if value="${surface_name == 'right_aileron'}">
          <xacro:insert_block name="right_aileron_coeffs"/>
        </xacro:if>
        <xacro:if value="${surface_name == 'rudder'}">
          <xacro:insert_block name="rudder_coeffs"/>
        </xacro:if>
        <xacro:if value="${surface_name == 'elevator'}">
          <xacro:insert_block name="elevator_coeffs"/>
        </xacro:if>
        <forward>1 0 0</forward>
        <link_name>${ns}/base_link</link_name>
        <control_joint_name>${ns}/${surface_name}_joint</control_joint_name>
      </plugin>
    </gazebo>
  </xacro:macro>
</robot>

