<?xml version="1.0"?>
<robot xmlns:xacro="http://ros.org/wiki/xacro">
  <xacro:macro name="plane_prop" params="ns *origin">
    <link name="${ns}/propeller">
      <inertial>
        <!--Look in iris.xacro or plane.xacro for definition -->
        <origin xyz="0 0 0" rpy="0 0 0" />
        <xacro:insert_block name="rotor_inertia" />
      </inertial>

      <visual>
        <geometry>
          <mesh filename="${mesh_root}/cessna_prop.dae" scale="0.1 0.1 0.1"/>
        </geometry>
      </visual>
    </link>

    <joint name="${ns}/propeller_joint" type="continuous">
      <xacro:insert_block name="origin" />
      <parent link="${ns}/base_link" />
      <child link="${ns}/propeller" />
      <axis xyz="1 0 0"/>
      <dynamics damping="0.001"/>
    </joint>

    <gazebo reference="${ns}/propeller">
        <material>Gazebo/Blue</material>
    </gazebo>

    <gazebo>
      <plugin name="propeller_top_blade" filename="libLiftDragPlugin.so">
        <a0>0.4</a0>
        <cla>4.752798721</cla>
        <cda>0.6417112299</cda>
        <cma>0</cma>
        <alpha_stall>1.5</alpha_stall>
        <cla_stall>-3.85</cla_stall>
        <cda_stall>-0.9233984055</cda_stall>
        <cma_stall>0</cma_stall>
        <cp>-0.37 0 0.77</cp>
        <area>.0001</area>
        <air_density>1.2041</air_density>
        <forward>0 -1 0</forward>
        <upward>1 0 0</upward>
        <link_name>${ns}/propeller</link_name>
      </plugin>
      <plugin name="propeller_bottom_blade" filename="libLiftDragPlugin.so">
        <a0>0.4</a0>
        <cla>4.752798721</cla>
        <cda>0.6417112299</cda>
        <cma>0</cma>
        <alpha_stall>1.5</alpha_stall>
        <cla_stall>-3.85</cla_stall>
        <cda_stall>-0.9233984055</cda_stall>
        <cma_stall>0</cma_stall>
        <cp>-0.37 0 -0.77</cp>
        <area>.0001</area>
        <air_density>1.2041</air_density>
        <forward>0 1 0</forward>
        <upward>1 0 0</upward>
        <link_name>${ns}/propeller</link_name>
      </plugin>
    </gazebo>
  </xacro:macro>
</robot>
