<?xml version="1.0"?>
<robot xmlns:xacro="http://ros.org/wiki/xacro">
  <xacro:macro name="rotor" params="ns motor_number prop_dir *origin">
    <link name="${ns}/rotor_${motor_number}">
      <inertial>
        <!--Look in iris.xacro or plane.xacro for definition -->
        <xacro:insert_block name="rotor_inertia" />
      </inertial>

      <collision>
        <geometry>
          <cylinder length="0.005" radius="0.1" />
        </geometry>
      </collision>

      <visual>
        <geometry>
          <mesh filename="${mesh_root}/iris_prop_${prop_dir}.dae" scale="1 1 1" />
        </geometry>
      </visual>
    </link>
    <joint name="${ns}/rotor_${motor_number}_joint" type="revolute">
      <xacro:insert_block name="origin" />
      <parent link="${ns}/base_link" />
      <child link="${ns}/rotor_${motor_number}" />
      <axis xyz="0 0 1"/>
      <dynamics damping="0.004"/>
      <limit effort="-1" velocity="-1" lower="-1e+16" upper="1e+16" />
    </joint>

    <gazebo reference="${ns}/rotor_${motor_number}">
      <xacro:if value="${motor_number == 0 or motor_number == 2}">
        <material>Gazebo/Blue</material>
      </xacro:if>
      <xacro:if value="${motor_number == 1 or motor_number == 3}">
        <material>Gazebo/Grey</material>
      </xacro:if>
    </gazebo>

    <gazebo>
      <plugin name="rotor_${motor_number}_blade_1" filename="libLiftDragPlugin.so">
        <a0>0.3</a0>
        <alpha_stall>1.4</alpha_stall>
        <cla>4.2500</cla>
        <cda>0.10</cda>
        <cma>0.00</cma>
        <cla_stall>-0.025</cla_stall>
        <cda_stall>0.0</cda_stall>
        <cma_stall>0.0</cma_stall>
        <area>0.002</area>
        <air_density>1.2041</air_density>
        <cp>0.084 0 0</cp>
        <xacro:if value="${prop_dir == 'ccw'}"><forward>0 1 0</forward></xacro:if>
        <xacro:if value="${prop_dir == 'cw'}"><forward>0 -1 0</forward></xacro:if>
        <upward>0 0 1</upward>
        <link_name>${ns}/rotor_${motor_number}</link_name>
      </plugin>
      <plugin name="rotor_${motor_number}_blade_2" filename="libLiftDragPlugin.so">
        <a0>0.3</a0>
        <alpha_stall>1.4</alpha_stall>
        <cla>4.2500</cla>
        <cda>0.10</cda>
        <cma>0.00</cma>
        <cla_stall>-0.025</cla_stall>
        <cda_stall>0.0</cda_stall>
        <cma_stall>0.0</cma_stall>
        <area>0.002</area>
        <air_density>1.2041</air_density>
        <cp>-0.084 0 0</cp>
        <xacro:if value="${prop_dir == 'ccw'}"><forward>0 -1 0</forward></xacro:if>
        <xacro:if value="${prop_dir == 'cw'}"><forward>0 1 0</forward></xacro:if>
        <upward>0 0 1</upward>
        <link_name>${ns}/rotor_${motor_number}</link_name>
      </plugin>
    </gazebo>
  </xacro:macro>
</robot>
